<?xml version="1.0" ?>
<robot name="rx150" xmlns:xacro="http://ros.org/wiki/xacro">
  <material name="interbotix_black">
    <!--    <texture filename="rx150_meshes/interbotix_black.png"/>-->
    <color rgba="0.5 0.5 0.5 1"/>
  </material>
  <link name="rx150/$(base_link_frame)">
    <visual>
      <origin rpy="0 0 -1.570796326795" xyz="0 0 0"/>
      <geometry>
        <mesh filename="rx150_meshes/rx150_1_base.stl" scale="0.001 0.001 0.001"/>
      </geometry>
      <material name="interbotix_black"/>
    </visual>
    <collision>
      <origin rpy="0 0 0" xyz="-0.04 0 0"/>
      <geometry>
        <box size="0.25 0.16 0.12"/>
      </geometry>
      <material name="interbotix_black"/>
    </collision>
    <inertial>
      <origin rpy="0 0 1.570796326795" xyz="-0.0354501000 -0.0033581300 0.0253418000"/>
      <mass value="0.766135"/>
      <inertia ixx="0.0033540000" ixy="-0.0001247000" ixz="0.0000110500" iyy="0.0013570000" iyz="0.0002102000" izz="0.0041110000"/>
    </inertial>
  </link>
  <joint name="waist" type="revolute">
    <axis xyz="0 0 1"/>
    <limit effort="8" lower="-3.14158265359" upper="3.14158265359" velocity="3.14159265359"/>
    <origin rpy="0 0 0" xyz="0 0 0.06566"/>
    <parent link="rx150/$(base_link_frame)"/>
    <child link="rx150/shoulder_link"/>
    <dynamics friction="0.1"/>
  </joint>
  <link name="rx150/shoulder_link">
    <visual>
      <origin rpy="0 0 -1.570796326795" xyz="0 0 0.0015"/>
      <geometry>
        <mesh filename="rx150_meshes/rx150_2_shoulder.stl" scale="0.001 0.001 0.001"/>
      </geometry>
      <material name="interbotix_black"/>
    </visual>
    <collision> 
      <origin rpy="0 0 0" xyz="0 0 0.02"/>
      <geometry>
        <box size="0.05 0.04 0.03"/>
      </geometry>
      <material name="interbotix_black"/>
    </collision>
    <inertial>
      <origin rpy="0 0 1.570796326795" xyz="-0.0001275490 -0.0001847470 0.0079473000"/>
      <mass value="0.257774"/>
      <inertia ixx="0.0002195000" ixy="-0.0000000045" ixz="0.0000010964" iyy="0.0002226000" iyz="0.0000001746" izz="0.0002898000"/>
    </inertial>
  </link>
  <joint name="shoulder" type="revolute">
    <axis xyz="0 1 0"/>
    <!--    <limit effort="18" lower="${radians(-106)}" upper="${radians(100)}" velocity="${pi}"/>-->
    <limit effort="18" lower="-1.85005" upper="1.74533" velocity="3.14159265359"/>
    <origin rpy="0 0 0" xyz="0 0 0.03891"/>
    <parent link="rx150/shoulder_link"/>
    <child link="rx150/upper_arm_link"/>
    <dynamics friction="0.1"/>
  </joint>
  <link name="rx150/upper_arm_link">
    <visual>
      <origin rpy="0 0 1.570796326795" xyz="0 0 0"/>
      <geometry>
        <mesh filename="rx150_meshes/rx150_3_upper_arm.stl" scale="0.001 0.001 0.001"/>
      </geometry>
      <material name="interbotix_black"/>
    </visual>
    <collision>
      <origin rpy="0 0 0" xyz="0 0 0.1"/>
      <geometry>
        <box size="0.05 0.05 0.13"/>
      </geometry>
      <material name="interbotix_black"/>
    </collision>
    <inertial>
      <origin rpy="0 0 1.570796326795" xyz="0.0125618000 -0.0001240170 0.1067620000"/>
      <mass value="0.283759"/>
      <inertia ixx="0.0008609000" ixy="-0.0000009758" ixz="0.0000015061" iyy="0.0007957000" iyz="0.0001518000" izz="0.0001568000"/>
    </inertial>
  </link>
  <joint name="elbow" type="revolute">
    <axis xyz="0 1 0"/>
    <!--    <limit effort="13" lower="${radians(-102)}" upper="${radians(95)}" velocity="${pi}"/>-->
    <limit effort="13" lower="-1.78024" upper="1.65806" velocity="3.14159265359"/>
    <origin rpy="0 0 0" xyz="0.05 0 0.15"/>
    <parent link="rx150/upper_arm_link"/>
    <child link="rx150/forearm_link"/>
    <dynamics friction="0.1"/>
  </joint>
  <link name="rx150/forearm_link">
    <visual>
      <origin rpy="0 0 1.570796326795" xyz="0 0 0"/>
      <geometry>
        <mesh filename="rx150_meshes/rx150_4_forearm.stl" scale="0.001 0.001 0.001"/>
      </geometry>
      <material name="interbotix_black"/>
    </visual>
    <collision>
      <origin rpy="0 0 0" xyz="0.07 0 0"/>
      <geometry>
        <box size="0.1 0.05 0.05"/>
      </geometry>
      <material name="interbotix_black"/>
    </collision>
    <inertial>
      <origin rpy="0 0 1.570796326795" xyz="0.0850900000 0.0004048240 0.0000000000"/>
      <mass value="0.23568"/>
      <inertia ixx="0.0004693000" ixy="-0.0000013550" ixz="0.0000000000" iyy="0.0000624200" iyz="0.0000000000" izz="0.0004895000"/>
    </inertial>
  </link>
  <joint name="wrist_angle" type="revolute">
    <axis xyz="0 1 0"/>
    <!--    <limit effort="5" lower="${radians(-100)}" upper="${radians(123)}" velocity="${pi}"/>-->
    <limit effort="5" lower="-1.74533" upper="2.14675" velocity="3.14159265359"/>
    <origin rpy="0 0 0" xyz="0.15 0 0"/>
    <parent link="rx150/forearm_link"/>
    <child link="rx150/wrist_link"/>
    <dynamics friction="0.1"/>
  </joint>
  <link name="rx150/wrist_link">
    <visual>
      <origin rpy="0 0 1.570796326795" xyz="0 0 0"/>
      <geometry>
        <mesh filename="rx150_meshes/rx150_5_wrist.stl" scale="0.001 0.001 0.001"/>
      </geometry>
      <material name="interbotix_black"/>
    </visual>
    <collision>
      <origin rpy="0 0 0" xyz="0.03 0 0"/>
      <geometry>
        <box size="0.04 0.05 0.05"/>
      </geometry>
      <material name="interbotix_black"/>
    </collision>
    <inertial>
      <origin rpy="0 0 1.570796326795" xyz="0.0423600000 -0.0000104110 0.0105770000"/>
      <mass value="0.084957"/>
      <inertia ixx="0.0000308200" ixy="0.0000000191" ixz="0.0000000023" iyy="0.0000282200" iyz="0.0000025481" izz="0.0000315200"/>
    </inertial>
  </link>
  <joint name="wrist_rotate" type="revolute">
    <axis xyz="1 0 0"/>
    <limit effort="1" lower="-3.14158265359" upper="3.14158265359" velocity="3.14159265359"/>
    <origin rpy="0 0 0" xyz="0.065 0 0"/>
    <parent link="rx150/wrist_link"/>
    <child link="rx150/gripper_link"/>
    <dynamics friction="0.1"/>
  </joint>
  <link name="rx150/gripper_link">
    <visual>
      <origin rpy="0 0 1.570796326795" xyz="-0.02 0 0"/>
      <geometry>
        <mesh filename="rx150_meshes/rx150_6_gripper.stl" scale="0.001 0.001 0.001"/>
      </geometry>
      <material name="interbotix_black"/>
    </visual>
    <collision>
      <origin rpy="0 0 0" xyz="0.01 0 0"/>
      <geometry>
        <box size="0.03 0.05 0.05"/>
      </geometry>
      <material name="interbotix_black"/>
    </collision>
    <inertial>
      <origin rpy="0 0 1.570796326795" xyz="0.0216300000 0.0000000000 0.0114100000"/>
      <mass value="0.072885"/>
      <inertia ixx="0.0000253700" ixy="0.0000000000" ixz="0.0000000000" iyy="0.0000183600" iyz="0.0000004340" izz="0.0000167400"/>
    </inertial>
  </link>
  <joint name="ee_arm" type="fixed">
    <axis xyz="1 0 0"/>
    <origin rpy="0 0 0" xyz="0.043 0 0"/>
    <parent link="rx150/gripper_link"/>
    <child link="rx150/ee_arm_link"/>
  </joint>
  <link name="rx150/ee_arm_link">
    <inertial>
      <mass value="0.001"/>
      <inertia ixx="0.001" ixy="0" ixz="0" iyy="0.001" iyz="0" izz="0.001"/>
    </inertial>
  </link>
  <!-- If the gripper bar is being used, then also add the gripper bar -->
  <joint name="gripper_bar" type="fixed">
    <axis xyz="1 0 0"/>
    <origin rpy="0 0 0" xyz="0 0 0"/>
    <parent link="rx150/ee_arm_link"/>
    <child link="rx150/gripper_bar_link"/>
  </joint>
  <link name="rx150/gripper_bar_link">
    <visual>
      <origin rpy="0 0 1.570796326795" xyz="-0.063 0 0"/>
      <geometry>
        <mesh filename="rx150_meshes/rx150_8_gripper_bar.stl" scale="0.001 0.001 0.001"/>
      </geometry>
      <material name="interbotix_black"/>
    </visual>
    <collision>
      <origin rpy="0 0 0" xyz="0 0 0"/>
      <geometry>
        <box size="0.03 0.12 0.03"/>
      </geometry>
      <material name="interbotix_black"/>
    </collision>
    <inertial>
      <origin rpy="0 0 1.570796326795" xyz="0.0096870000 0.0000005660 0.0049620000"/>
      <mass value="0.034199"/>
      <inertia ixx="0.0000074125" ixy="-0.0000000008" ixz="-0.0000000006" iyy="0.0000284300" iyz="-0.0000013889" izz="0.0000286000"/>
    </inertial>
  </link>
  <joint name="ee_bar" type="fixed">
    <axis xyz="1 0 0"/>
    <origin rpy="0 0 0" xyz="0.023 0 0"/>
    <parent link="rx150/gripper_bar_link"/>
    <child link="rx150/fingers_link"/>
  </joint>
  <link name="rx150/fingers_link">
    <inertial>
      <mass value="0.001"/>
      <inertia ixx="0.001" ixy="0" ixz="0" iyy="0.001" iyz="0" izz="0.001"/>
    </inertial>
  </link>
  <!-- If the gripper fingers are being used, add those as well -->
  <joint name="left_finger" type="prismatic">
    <axis xyz="0 1 0"/>
    <limit effort="5" lower="0.015" upper="0.037" velocity="1"/>
    <origin rpy="0 0 0" xyz="0 0 0"/>
    <parent link="rx150/fingers_link"/>
    <child link="rx150/left_finger_link"/>
    <dynamics friction="0.1"/>
  </joint>
  <link name="rx150/left_finger_link">
    <visual>
      <origin rpy="3.14159265359 3.14159265359 0" xyz="0 0.005 0"/>
      <geometry>
        <mesh filename="rx150_meshes/rx150_9_gripper_finger.stl" scale="0.001 0.001 0.001"/>
      </geometry>
      <material name="interbotix_black"/>
    </visual>
    <collision>
      <origin rpy="0 0 0" xyz="0.02 0 0"/>
      <geometry>
        <box size="0.05 0.01 0.03"/>
      </geometry>
      <material name="interbotix_black"/>
    </collision>
    <inertial>
      <origin rpy="3.14159265359 3.14159265359 1.570796326795" xyz="0.0138160000 0.0000000000 0.0000000000"/>
      <mass value="0.016246"/>
      <inertia ixx="0.0000047310" ixy="-0.0000004560" ixz="0.0000000000" iyy="0.0000015506" iyz="0.0000000000" izz="0.0000037467"/>
    </inertial>
  </link>
  <joint name="right_finger" type="prismatic">
    <axis xyz="0 1 0"/>
    <limit effort="5" lower="-0.037" upper="-0.015" velocity="1"/>
    <origin rpy="0 0 0" xyz="0 0 0"/>
    <parent link="rx150/fingers_link"/>
    <child link="rx150/right_finger_link"/>
    <dynamics friction="0.1"/>
    <!--        <xacro:unless value="${load_gazebo_configs}">-->
    <mimic joint="left_finger" multiplier="-1" offset="0"/>
    <!--        </xacro:unless>-->
  </joint>
  <link name="rx150/right_finger_link">
    <visual>
      <origin rpy="0 3.14159265359 0" xyz="0 -0.005 0"/>
      <geometry>
        <mesh filename="rx150_meshes/rx150_9_gripper_finger.stl" scale="0.001 0.001 0.001"/>
      </geometry>
      <material name="interbotix_black"/>
    </visual>
    <collision>
      <origin rpy="0 0 0" xyz="0.02 0 0"/>
      <geometry>
        <box size="0.05 0.01 0.03"/>
      </geometry>
      <material name="interbotix_black"/>
    </collision>
    <inertial>
      <origin rpy="0 3.14159265359 1.570796326795" xyz="0.0138160000 0.0000000000  0.0000000000"/>
      <mass value="0.016246"/>
      <inertia ixx="0.0000047310" ixy="0.0000004560" ixz="0.0000000000" iyy="0.0000015506" iyz="0.0000000000" izz="0.0000037467"/>
    </inertial>
  </link>
  <joint name="ee_gripper" type="fixed">
    <axis xyz="1 0 0"/>
    <origin rpy="0 0 0" xyz="0.027575 0 0"/>
    <parent link="rx150/fingers_link"/>
    <child link="rx150/ee_gripper_link"/>
  </joint>
  <link name="rx150/ee_gripper_link">
    <inertial>
      <mass value="0.001"/>
      <inertia ixx="0.001" ixy="0" ixz="0" iyy="0.001" iyz="0" izz="0.001"/>
    </inertial>
  </link>
</robot>
